{"trial_id": "001", "hyperparameters": {"space": [{"class_name": "Choice", "config": {"name": "units", "default": 5, "conditions": [], "values": [5, 20, 40], "ordered": true}}, {"class_name": "Choice", "config": {"name": "activation", "default": "relu", "conditions": [], "values": ["relu"], "ordered": false}}, {"class_name": "Choice", "config": {"name": "dropout", "default": 0.1, "conditions": [], "values": [0.1, 0.3, 0.5], "ordered": true}}, {"class_name": "Choice", "config": {"name": "learning_rate", "default": 0.001, "conditions": [], "values": [0.001, 0.1, 1.0], "ordered": true}}, {"class_name": "Choice", "config": {"name": "max_grad_norm", "default": 0.01, "conditions": [], "values": [0.01, 0.1, 1.0, 10.0], "ordered": true}}, {"class_name": "Choice", "config": {"name": "batch_size", "default": 256, "conditions": [], "values": [256, 512, 1024], "ordered": true}}], "values": {"units": 5, "activation": "relu", "dropout": 0.1, "learning_rate": 0.001, "max_grad_norm": 0.01, "batch_size": 512}}, "metrics": {"metrics": {}}, "score": null, "best_step": 0, "status": "FAILED", "message": "Traceback (most recent call last):\n  File \"c:\\Users\\NPW\\anaconda3\\Lib\\site-packages\\keras_tuner\\src\\engine\\base_tuner.py\", line 274, in _try_run_and_update_trial\n    self._run_and_update_trial(trial, *fit_args, **fit_kwargs)\n  File \"c:\\Users\\NPW\\anaconda3\\Lib\\site-packages\\keras_tuner\\src\\engine\\base_tuner.py\", line 239, in _run_and_update_trial\n    results = self.run_trial(trial, *fit_args, **fit_kwargs)\n              ^^^^^^^^^^^^^^^^^^^^^^^^^^^^^^^^^^^^^^^^^^^^^^\n  File \"c:\\Users\\NPW\\anaconda3\\Lib\\site-packages\\keras_tuner\\src\\engine\\tuner.py\", line 314, in run_trial\n    obj_value = self._build_and_fit_model(trial, *args, **copied_kwargs)\n                ^^^^^^^^^^^^^^^^^^^^^^^^^^^^^^^^^^^^^^^^^^^^^^^^^^^^^^^^\n  File \"c:\\Users\\NPW\\anaconda3\\Lib\\site-packages\\keras_tuner\\src\\engine\\tuner.py\", line 233, in _build_and_fit_model\n    results = self.hypermodel.fit(hp, model, *args, **kwargs)\n              ^^^^^^^^^^^^^^^^^^^^^^^^^^^^^^^^^^^^^^^^^^^^^^^\n  File \"c:\\Users\\NPW\\Documents\\KLuan\\TSMOM-2.0\\model.py\", line 203, in fit\n    return model.fit(\n           ^^^^^^^^^^\n  File \"c:\\Users\\NPW\\anaconda3\\Lib\\site-packages\\keras\\src\\utils\\traceback_utils.py\", line 122, in error_handler\n    raise e.with_traceback(filtered_tb) from None\n  File \"c:\\Users\\NPW\\anaconda3\\Lib\\site-packages\\keras\\src\\layers\\input_spec.py\", line 227, in assert_input_compatibility\n    raise ValueError(\nValueError: Exception encountered when calling Sequential.call().\n\n\u001b[1mInput 0 of layer \"dense\" is incompatible with the layer: expected axis -1 of input shape to have value 12, but received input with shape (None, 11)\u001b[0m\n\nArguments received by Sequential.call():\n  \u2022 inputs=tf.Tensor(shape=(None, 11), dtype=float32)\n  \u2022 training=True\n  \u2022 mask=None\n"}